Workbook
Name LookUpFinalOption: 'LookUp Sheet'!$B$3
Name TableName: 'LookUp Sheet'!$B$6

Sheet LookUp Sheet
B2: LookUpOptions
B3: Master
B5: Look Up Table | D5: Base table | E5: Master table | H5: Datalake table
B6: marketing_extract | D6: {=IF(LookUpFinalOption="Base", TableName, IF(LookUpFinalOption="Master", IFERROR(_xlfn._xlws.FILTER(MasterTables[Helper Tables], MasterTables[MasterTable]=TableName), "Not Found"), "None"))} -> dss_tblstudentinfo | E6: {=IF(LookUpFinalOption="Master", IFERROR(_xlfn._xlws.FILTER(MasterTables[MasterTable], MasterTables[MasterTable]=TableName), "Not Found"), "None")} -> marketing_extract | H6: =Formulas!B8 -> dss_caautoclubsocal201229_tblstudentinfo, dss_caautoclubtexas210622_tblstudentinfo, dss_meaaamaine211013_tblstudentinfo, dss_nhaaanh211015_tblstudentinfo, dss_ohautoclubohio220913_tblstudentinfo
D10: Datalake Jobs | E10: Base glue jobs | F10: Master glue job
D11: =Datalake!C2 -> ace_da_dss_datalake | E11: =Formulas!B11 -> ace-da-dss-base-tblstudentinfo | F11: {=IF(LookUpFinalOption="Master", IFERROR(_xlfn._xlws.FILTER(MasterTables[MasterGlueJob], MasterTables[MasterTable]=TableName), "Not Found"), "None")} -> ace-da-dss-student-master
D13: Control M Datalake | E13: Control M Base | F13: Control M Master
D14: =Datalake!E2 -> ace-da-dss-staging-to-datalake | E14: =Formulas!B14 -> DEO1104O_DSS_AWS_TBLSTUDENTINFO_TO_AWS_BASE_LOAD | F14: {=IF(LookUpFinalOption="Master", IFERROR(_xlfn._xlws.FILTER(MasterTables[MasterControlM], MasterTables[MasterTable]=TableName), "Not Found"), "None")} -> DEO1151O_DSS_STUDENT_MASTER_TO_AWS_MASTER_LOAD
D16: Control M SFTP | E16: SFTP location
D17: {=IF(LookUpFinalOption="Master", IFERROR(_xlfn._xlws.FILTER(MasterTables[SFTP Job], MasterTables[MasterTable]=TableName), "Not Found"), "None")} -> MCE1428O_DSS_MktgFile_AWS_TO_Hadoop | E17: {=IF(LookUpFinalOption="Master", IFERROR(_xlfn._xlws.FILTER(MasterTables[SFTP Location], MasterTables[MasterTable]=TableName), "Not Found"), "None")} -> /workspace/projects/dss/sh_scripts/marketing_sftp.sh

Sheet Formulas
A1: LookUpOptions | G1: {=TRANSPOSE(_xlfn.TEXTSPLIT(CLEAN(TRIM(B7)), ","))} -> dss_tblstudentinfo | H1: =IF(ISBLANK(G1), FALSE, TRUE) -> TRUE | I1: {=IF(G1<>"", _xlfn._xlws.FILTER(BaseTables[Helper Tables], BaseTables[BaseTable]=G1, "No Match"))} -> dss_caautoclubsocal201229_tblstudentinfo, dss_caautoclubtexas210622_tblstudentinfo, dss_meaaamaine211013_tblstudentinfo, dss_nhaaanh211015_tblstudentinfo, dss_ohautoclubohio220913_tblstudentinfo | J1: {=IF(G1<>"", _xlfn._xlws.FILTER(BaseTables[BaseGlueJob], BaseTables[BaseTable]=G1, "No Match"))} -> ace-da-dss-base-tblstudentinfo | K1: {=IF(G1<>"", _xlfn._xlws.FILTER(BaseTables[BaseControlM], BaseTables[BaseTable]=G1, "No Match"))} -> DEO1104O_DSS_AWS_TBLSTUDENTINFO_TO_AWS_BASE_LOAD
A2: Base | H2: =IF(ISBLANK(G2), FALSE, TRUE) -> FALSE | I2: {=IF(G2<>"", _xlfn._xlws.FILTER(BaseTables[Helper Tables], BaseTables[BaseTable]=G2, "No Match"))} -> FALSE | J2: {=IF(G2<>"", _xlfn._xlws.FILTER(BaseTables[BaseGlueJob], BaseTables[BaseTable]=G2, "No Match"))} -> FALSE | K2: {=IF(G2<>"", _xlfn._xlws.FILTER(BaseTables[BaseControlM], BaseTables[BaseTable]=G2, "No Match"))} -> FALSE
A3: Master | H3: =IF(ISBLANK(G3), FALSE, TRUE) -> FALSE | I3: {=IF(G3<>"", _xlfn._xlws.FILTER(BaseTables[Helper Tables], BaseTables[BaseTable]=G3, "No Match"))} -> FALSE | J3: {=IF(G3<>"", _xlfn._xlws.FILTER(BaseTables[BaseGlueJob], BaseTables[BaseTable]=G3, "No Match"))} -> FALSE | K3: {=IF(G3<>"", _xlfn._xlws.FILTER(BaseTables[BaseControlM], BaseTables[BaseTable]=G3, "No Match"))} -> FALSE
H4: =IF(ISBLANK(G4), FALSE, TRUE) -> FALSE | I4: {=IF(G4<>"", _xlfn._xlws.FILTER(BaseTables[Helper Tables], BaseTables[BaseTable]=G4, "No Match"))} -> FALSE | J4: {=IF(G4<>"", _xlfn._xlws.FILTER(BaseTables[BaseGlueJob], BaseTables[BaseTable]=G4, "No Match"))} -> FALSE | K4: {=IF(G4<>"", _xlfn._xlws.FILTER(BaseTables[BaseControlM], BaseTables[BaseTable]=G4, "No Match"))} -> FALSE
H5: =IF(ISBLANK(G5), FALSE, TRUE) -> FALSE | I5: {=IF(G5<>"", _xlfn._xlws.FILTER(BaseTables[Helper Tables], BaseTables[BaseTable]=G5, "No Match"))} -> FALSE | J5: {=IF(G5<>"", _xlfn._xlws.FILTER(BaseTables[BaseGlueJob], BaseTables[BaseTable]=G5, "No Match"))} -> FALSE | K5: {=IF(G5<>"", _xlfn._xlws.FILTER(BaseTables[BaseControlM], BaseTables[BaseTable]=G5, "No Match"))} -> FALSE
B6: Datalake Table Calculation | H6: =IF(ISBLANK(G6), FALSE, TRUE) -> FALSE | I6: {=IF(G6<>"", _xlfn._xlws.FILTER(BaseTables[Helper Tables], BaseTables[BaseTable]=G6, "No Match"))} -> FALSE | J6: {=IF(G6<>"", _xlfn._xlws.FILTER(BaseTables[BaseGlueJob], BaseTables[BaseTable]=G6, "No Match"))} -> FALSE | K6: {=IF(G6<>"", _xlfn._xlws.FILTER(BaseTables[BaseControlM], BaseTables[BaseTable]=G6, "No Match"))} -> FALSE
B7: ='LookUp Sheet'!D6 -> dss_tblstudentinfo | H7: =IF(ISBLANK(G7), FALSE, TRUE) -> FALSE | I7: {=IF(G7<>"", _xlfn._xlws.FILTER(BaseTables[Helper Tables], BaseTables[BaseTable]=G7, "No Match"))} -> FALSE | J7: {=IF(G7<>"", _xlfn._xlws.FILTER(BaseTables[BaseGlueJob], BaseTables[BaseTable]=G7, "No Match"))} -> FALSE | K7: {=IF(G7<>"", _xlfn._xlws.FILTER(BaseTables[BaseControlM], BaseTables[BaseTable]=G7, "No Match"))} -> FALSE
B8: {=_xlfn.TEXTJOIN(CHAR(10), TRUE, _xlfn._xlws.FILTER(Formulas!I1:I18, (Formulas!I1:I18<>FALSE)*(Formulas!I1:I18<>"FALSE")))} -> dss_caautoclubsocal201229_tblstudentinfo, dss_caautoclubtexas210622_tblstudentinfo, dss_meaaamaine211013_tblstudentinfo, dss_nhaaanh211015_tblstudentinfo, dss_ohautoclubohio220913_tblstudentinfo | H8: =IF(ISBLANK(G8), FALSE, TRUE) -> FALSE | I8: {=IF(G8<>"", _xlfn._xlws.FILTER(BaseTables[Helper Tables], BaseTables[BaseTable]=G8, "No Match"))} -> FALSE | J8: {=IF(G8<>"", _xlfn._xlws.FILTER(BaseTables[BaseGlueJob], BaseTables[BaseTable]=G8, "No Match"))} -> FALSE | K8: {=IF(G8<>"", _xlfn._xlws.FILTER(BaseTables[BaseControlM], BaseTables[BaseTable]=G8, "No Match"))} -> FALSE
H9: =IF(ISBLANK(G9), FALSE, TRUE) -> FALSE | I9: {=IF(G9<>"", _xlfn._xlws.FILTER(BaseTables[Helper Tables], BaseTables[BaseTable]=G9, "No Match"))} -> FALSE | J9: {=IF(G9<>"", _xlfn._xlws.FILTER(BaseTables[BaseGlueJob], BaseTables[BaseTable]=G9, "No Match"))} -> FALSE | K9: {=IF(G9<>"", _xlfn._xlws.FILTER(BaseTables[BaseControlM], BaseTables[BaseTable]=G9, "No Match"))} -> FALSE
B10: Base Job Calculation | H10: =IF(ISBLANK(G10), FALSE, TRUE) -> FALSE | I10: {=IF(G10<>"", _xlfn._xlws.FILTER(BaseTables[Helper Tables], BaseTables[BaseTable]=G10, "No Match"))} -> FALSE | J10: {=IF(G10<>"", _xlfn._xlws.FILTER(BaseTables[BaseGlueJob], BaseTables[BaseTable]=G10, "No Match"))} -> FALSE | K10: {=IF(G10<>"", _xlfn._xlws.FILTER(BaseTables[BaseControlM], BaseTables[BaseTable]=G10, "No Match"))} -> FALSE
B11: {=_xlfn.TEXTJOIN("," & CHAR(10), TRUE, _xlfn.UNIQUE(_xlfn._xlws.FILTER(Formulas!J1:J18, (Formulas!J1:J18<>FALSE)*(Formulas!J1:J18<>"FALSE"))))} -> ace-da-dss-base-tblstudentinfo | H11: =IF(ISBLANK(G11), FALSE, TRUE) -> FALSE | I11: {=IF(G11<>"", _xlfn._xlws.FILTER(BaseTables[Helper Tables], BaseTables[BaseTable]=G11, "No Match"))} -> FALSE | J11: {=IF(G11<>"", _xlfn._xlws.FILTER(BaseTables[BaseGlueJob], BaseTables[BaseTable]=G11, "No Match"))} -> FALSE | K11: {=IF(G11<>"", _xlfn._xlws.FILTER(BaseTables[BaseControlM], BaseTables[BaseTable]=G11, "No Match"))} -> FALSE
H12: =IF(ISBLANK(G12), FALSE, TRUE) -> FALSE | I12: {=IF(G12<>"", _xlfn._xlws.FILTER(BaseTables[Helper Tables], BaseTables[BaseTable]=G12, "No Match"))} -> FALSE | J12: {=IF(G12<>"", _xlfn._xlws.FILTER(BaseTables[BaseGlueJob], BaseTables[BaseTable]=G12, "No Match"))} -> FALSE | K12: {=IF(G12<>"", _xlfn._xlws.FILTER(BaseTables[BaseControlM], BaseTables[BaseTable]=G12, "No Match"))} -> FALSE
B13: Base Control M Calculation | H13: =IF(ISBLANK(G13), FALSE, TRUE) -> FALSE | I13: {=IF(G13<>"", _xlfn._xlws.FILTER(BaseTables[Helper Tables], BaseTables[BaseTable]=G13, "No Match"))} -> FALSE | J13: {=IF(G13<>"", _xlfn._xlws.FILTER(BaseTables[BaseGlueJob], BaseTables[BaseTable]=G13, "No Match"))} -> FALSE | K13: {=IF(G13<>"", _xlfn._xlws.FILTER(BaseTables[BaseControlM], BaseTables[BaseTable]=G13, "No Match"))} -> FALSE
B14: {=_xlfn.TEXTJOIN("," & CHAR(10), TRUE, _xlfn.UNIQUE(_xlfn._xlws.FILTER(Formulas!K1:K18, (Formulas!K1:K18<>FALSE)*(Formulas!K1:K18<>"FALSE"))))} -> DEO1104O_DSS_AWS_TBLSTUDENTINFO_TO_AWS_BASE_LOAD | H14: =IF(ISBLANK(G14), FALSE, TRUE) -> FALSE | I14: {=IF(G14<>"", _xlfn._xlws.FILTER(BaseTables[Helper Tables], BaseTables[BaseTable]=G14, "No Match"))} -> FALSE | J14: {=IF(G14<>"", _xlfn._xlws.FILTER(BaseTables[BaseGlueJob], BaseTables[BaseTable]=G14, "No Match"))} -> FALSE | K14: {=IF(G14<>"", _xlfn._xlws.FILTER(BaseTables[BaseControlM], BaseTables[BaseTable]=G14, "No Match"))} -> FALSE
H15: =IF(ISBLANK(G15), FALSE, TRUE) -> FALSE | I15: {=IF(G15<>"", _xlfn._xlws.FILTER(BaseTables[Helper Tables], BaseTables[BaseTable]=G15, "No Match"))} -> FALSE | J15: {=IF(G15<>"", _xlfn._xlws.FILTER(BaseTables[BaseGlueJob], BaseTables[BaseTable]=G15, "No Match"))} -> FALSE | K15: {=IF(G15<>"", _xlfn._xlws.FILTER(BaseTables[BaseControlM], BaseTables[BaseTable]=G15, "No Match"))} -> FALSE
H16: =IF(ISBLANK(G16), FALSE, TRUE) -> FALSE | I16: {=IF(G16<>"", _xlfn._xlws.FILTER(BaseTables[Helper Tables], BaseTables[BaseTable]=G16, "No Match"))} -> FALSE | J16: {=IF(G16<>"", _xlfn._xlws.FILTER(BaseTables[BaseGlueJob], BaseTables[BaseTable]=G16, "No Match"))} -> FALSE | K16: {=IF(G16<>"", _xlfn._xlws.FILTER(BaseTables[BaseControlM], BaseTables[BaseTable]=G16, "No Match"))} -> FALSE
H17: =IF(ISBLANK(G17), FALSE, TRUE) -> FALSE | I17: {=IF(G17<>"", _xlfn._xlws.FILTER(BaseTables[Helper Tables], BaseTables[BaseTable]=G17, "No Match"))} -> FALSE | J17: {=IF(G17<>"", _xlfn._xlws.FILTER(BaseTables[BaseGlueJob], BaseTables[BaseTable]=G17, "No Match"))} -> FALSE | K17: {=IF(G17<>"", _xlfn._xlws.FILTER(BaseTables[BaseControlM], BaseTables[BaseTable]=G17, "No Match"))} -> FALSE
H18: =IF(ISBLANK(G18), FALSE, TRUE) -> FALSE | I18: {=IF(G18<>"", _xlfn._xlws.FILTER(BaseTables[Helper Tables], BaseTables[BaseTable]=G18, "No Match"))} -> FALSE | J18: {=IF(G18<>"", _xlfn._xlws.FILTER(BaseTables[BaseGlueJob], BaseTables[BaseTable]=G18, "No Match"))} -> FALSE | K18: {=IF(G18<>"", _xlfn._xlws.FILTER(BaseTables[BaseControlM], BaseTables[BaseTable]=G18, "No Match"))} -> FALSE

Sheet Datalake
A1: DatalakeTable | B1: DatalakeS3Location | C1: DatalakeCrawler | D1: DatalakeGlueJob | E1: DatalakeControlM
A2: dss_caautoclubsocal201229_mstadjustmenttypes | B2: s3://ace-da-mc-dss-datalake-us-west-2-847515726144/datalake/CAAutoClubSoCal201229_mstAdjustmentTypes/ | C2: ace_da_dss_datalake | D2: ace-da-dss-staging-to-datalake | E2: ace-da-dss-staging-to-datalake
A3: dss_caautoclubsocal201229_mstappointmentstatus | B3: s3://ace-da-mc-dss-datalake-us-west-2-847515726144/datalake/CAAutoClubSoCal201229_mstAppointmentStatus/ | C3: ace_da_dss_datalake | D3: ace-da-dss-staging-to-datalake | E3: ace-da-dss-staging-to-datalake
A4: dss_caautoclubsocal201229_mstclassroomsessionstatus | B4: s3://ace-da-mc-dss-datalake-us-west-2-847515726144/datalake/CAAutoClubSoCal201229_mstClassroomSessionStatus/ | C4: ace_da_dss_datalake | D4: ace-da-dss-staging-to-datalake | E4: ace-da-dss-staging-to-datalake
A5: dss_caautoclubsocal201229_mstclassroomstatus | B5: s3://ace-da-mc-dss-datalake-us-west-2-847515726144/datalake/CAAutoClubSoCal201229_mstClassroomStatus/ | C5: ace_da_dss_datalake | D5: ace-da-dss-staging-to-datalake | E5: ace-da-dss-staging-to-datalake
A6: dss_caautoclubsocal201229_mstcreditcardtypes | B6: s3://ace-da-mc-dss-datalake-us-west-2-847515726144/datalake/CAAutoClubSoCal201229_mstCreditCardTypes/ | C6: ace_da_dss_datalake | D6: ace-da-dss-staging-to-datalake | E6: ace-da-dss-staging-to-datalake
A7: dss_caautoclubsocal201229_mstpaymenttypes | B7: s3://ace-da-mc-dss-datalake-us-west-2-847515726144/datalake/CAAutoClubSoCal201229_mstPaymentTypes/ | C7: ace_da_dss_datalake | D7: ace-da-dss-staging-to-datalake | E7: ace-da-dss-staging-to-datalake
A8: dss_caautoclubsocal201229_mststaffstatus | B8: s3://ace-da-mc-dss-datalake-us-west-2-847515726144/datalake/CAAutoClubSoCal201229_mstStaffStatus/ | C8: ace_da_dss_datalake | D8: ace-da-dss-staging-to-datalake | E8: ace-da-dss-staging-to-datalake
A9: dss_caautoclubsocal201229_mststafftype | B9: s3://ace-da-mc-dss-datalake-us-west-2-847515726144/datalake/CAAutoClubSoCal201229_mstStaffType/ | C9: ace_da_dss_datalake | D9: ace-da-dss-staging-to-datalake | E9: ace-da-dss-staging-to-datalake
A10: dss_caautoclubsocal201229_mststudentstatus | B10: s3://ace-da-mc-dss-datalake-us-west-2-847515726144/datalake/CAAutoClubSoCal201229_mstStudentStatus/ | C10: ace_da_dss_datalake | D10: ace-da-dss-staging-to-datalake | E10: ace-da-dss-staging-to-datalake
A11: dss_caautoclubsocal201229_mstvehiclestatus | B11: s3://ace-da-mc-dss-datalake-us-west-2-847515726144/datalake/CAAutoClubSoCal201229_mstVehicleStatus/ | C11: ace_da_dss_datalake | D11: ace-da-dss-staging-to-datalake | E11: ace-da-dss-staging-to-datalake
A12: dss_caautoclubsocal201229_mstvehicletype | B12: s3://ace-da-mc-dss-datalake-us-west-2-847515726144/datalake/CAAutoClubSoCal201229_mstVehicleType/ | C12: ace_da_dss_datalake | D12: ace-da-dss-staging-to-datalake | E12: ace-da-dss-staging-to-datalake
... A44: dss_caautoclubtexas210622_tblcrsessions | B44: s3://ace-da-mc-dss-datalake-us-west-2-847515726144/datalake/CAAutoClubTexas210622_TblCrSessions/ | C44: ace_da_dss_datalake | D44: ace-da-dss-staging-to-datalake | E44: ace-da-dss-staging-to-datalake
A45: dss_caautoclubtexas210622_tblhighschool | C45: ace_da_dss_datalake | D45: ace-da-dss-staging-to-datalake | E45: ace-da-dss-staging-to-datalake
A46: dss_caautoclubtexas210622_tblleads | B46: s3://ace-da-mc-dss-datalake-us-west-2-847515726144/datalake/CAAutoClubTexas210622_tblleads/ | C46: ace_da_dss_datalake | D46: ace-da-dss-staging-to-datalake | E46: ace-da-dss-staging-to-datalake
A47: dss_caautoclubtexas210622_tbllocation | B47: s3://ace-da-mc-dss-datalake-us-west-2-847515726144/datalake/CAAutoClubTexas210622_tbllocation/ | C47: ace_da_dss_datalake | D47: ace-da-dss-staging-to-datalake | E47: ace-da-dss-staging-to-datalake
A48: dss_caautoclubtexas210622_tblpackageinfo | B48: s3://ace-da-mc-dss-datalake-us-west-2-847515726144/datalake/CAAutoClubTexas210622_tblpackageinfo/ | C48: ace_da_dss_datalake | D48: ace-da-dss-staging-to-datalake | E48: ace-da-dss-staging-to-datalake
A49: dss_caautoclubtexas210622_tblpackagelocations | B49: s3://ace-da-mc-dss-datalake-us-west-2-847515726144/datalake/CAAutoClubTexas210622_tblpackageLocations/ | C49: ace_da_dss_datalake | D49: ace-da-dss-staging-to-datalake | E49: ace-da-dss-staging-to-datalake
A50: dss_caautoclubtexas210622_tblpackageproducts | B50: s3://ace-da-mc-dss-datalake-us-west-2-847515726144/datalake/CAAutoClubTexas210622_tblpackageproducts/ | C50: ace_da_dss_datalake | D50: ace-da-dss-staging-to-datalake | E50: ace-da-dss-staging-to-datalake
A51: dss_caautoclubtexas210622_tblproductinfo | B51: s3://ace-da-mc-dss-datalake-us-west-2-847515726144/datalake/CAAutoClubTexas210622_tblproductinfo/ | C51: ace_da_dss_datalake | D51: ace-da-dss-staging-to-datalake | E51: ace-da-dss-staging-to-datalake
A52: dss_caautoclubtexas210622_tblstaffinfo | B52: s3://ace-da-mc-dss-datalake-us-west-2-847515726144/datalake/CAAutoClubTexas210622_TblStaffInfo/ | C52: ace_da_dss_datalake | D52: ace-da-dss-staging-to-datalake | E52: ace-da-dss-staging-to-datalake
A53: dss_caautoclubtexas210622_tblstudentenrollment | B53: s3://ace-da-mc-dss-datalake-us-west-2-847515726144/datalake/CAAutoClubTexas210622_tblStudentEnrollment/ | C53: ace_da_dss_datalake | D53: ace-da-dss-staging-to-datalake | E53: ace-da-dss-staging-to-datalake
A54: dss_caautoclubtexas210622_tblstudentinfo | B54: s3://ace-da-mc-dss-datalake-us-west-2-847515726144/datalake/CAAutoClubTexas210622_tblStudentInfo/ | C54: ace_da_dss_datalake | D54: ace-da-dss-staging-to-datalake | E54: ace-da-dss-staging-to-datalake
A55: dss_caautoclubtexas210622_tblvehicleinfo | B55: s3://ace-da-mc-dss-datalake-us-west-2-847515726144/datalake/CAAutoClubTexas210622_tblVehicleInfo/ | C55: ace_da_dss_datalake | D55: ace-da-dss-staging-to-datalake | E55: ace-da-dss-staging-to-datalake
A56: dss_meaaamaine211013_mstadjustmenttypes | B56: s3://ace-da-mc-dss-datalake-us-west-2-847515726144/datalake/MEAAAMaine211013_mstAdjustmentTypes/ | C56: ace_da_dss_datalake | D56: ace-da-dss-staging-to-datalake | E56: ace-da-dss-staging-to-datalake
A57: dss_meaaamaine211013_mstappointmentstatus | B57: s3://ace-da-mc-dss-datalake-us-west-2-847515726144/datalake/MEAAAMaine211013_mstAppointmentStatus/ | C57: ace_da_dss_datalake | D57: ace-da-dss-staging-to-datalake | E57: ace-da-dss-staging-to-datalake
... A123: dss_ohautoclubohio220913_tblclassroom | B123: s3://ace-da-mc-dss-datalake-us-west-2-847515726144/datalake/OHAutoClubOhio220913_tblclassroom/ | C123: ace_da_dss_datalake | D123: ace-da-dss-staging-to-datalake | E123: ace-da-dss-staging-to-datalake
A124: dss_ohautoclubohio220913_tblcrattendance | C124: ace_da_dss_datalake | D124: ace-da-dss-staging-to-datalake | E124: ace-da-dss-staging-to-datalake
A125: dss_ohautoclubohio220913_tblcrsessions | B125: s3://ace-da-mc-dss-datalake-us-west-2-847515726144/datalake/OHAutoClubOhio220913_TblCrSessions/ | C125: ace_da_dss_datalake | D125: ace-da-dss-staging-to-datalake | E125: ace-da-dss-staging-to-datalake
A126: dss_ohautoclubohio220913_tblhighschool | C126: ace_da_dss_datalake | D126: ace-da-dss-staging-to-datalake | E126: ace-da-dss-staging-to-datalake
A127: dss_ohautoclubohio220913_tblleads | B127: s3://ace-da-mc-dss-datalake-us-west-2-847515726144/datalake/OHAutoClubOhio220913_tblleads/ | C127: ace_da_dss_datalake | D127: ace-da-dss-staging-to-datalake | E127: ace-da-dss-staging-to-datalake
A128: dss_ohautoclubohio220913_tbllocation | B128: s3://ace-da-mc-dss-datalake-us-west-2-847515726144/datalake/OHAutoClubOhio220913_tbllocation/ | C128: ace_da_dss_datalake | D128: ace-da-dss-staging-to-datalake | E128: ace-da-dss-staging-to-datalake
A129: dss_ohautoclubohio220913_tblpackageinfo | B129: s3://ace-da-mc-dss-datalake-us-west-2-847515726144/datalake/OHAutoClubOhio220913_tblpackageinfo/ | C129: ace_da_dss_datalake | D129: ace-da-dss-staging-to-datalake | E129: ace-da-dss-staging-to-datalake
A130: dss_ohautoclubohio220913_tblpackagelocations | B130: s3://ace-da-mc-dss-datalake-us-west-2-847515726144/datalake/OHAutoClubOhio220913_tblpackageLocations/ | C130: ace_da_dss_datalake | D130: ace-da-dss-staging-to-datalake | E130: ace-da-dss-staging-to-datalake
A131: dss_ohautoclubohio220913_tblpackageproducts | B131: s3://ace-da-mc-dss-datalake-us-west-2-847515726144/datalake/OHAutoClubOhio220913_tblpackageproducts/ | C131: ace_da_dss_datalake | D131: ace-da-dss-staging-to-datalake | E131: ace-da-dss-staging-to-datalake
A132: dss_ohautoclubohio220913_tblproductinfo | B132: s3://ace-da-mc-dss-datalake-us-west-2-847515726144/datalake/OHAutoClubOhio220913_tblproductinfo/ | C132: ace_da_dss_datalake | D132: ace-da-dss-staging-to-datalake | E132: ace-da-dss-staging-to-datalake
A133: dss_ohautoclubohio220913_tblstaffinfo | B133: s3://ace-da-mc-dss-datalake-us-west-2-847515726144/datalake/OHAutoClubOhio220913_TblStaffInfo/ | C133: ace_da_dss_datalake | D133: ace-da-dss-staging-to-datalake | E133: ace-da-dss-staging-to-datalake
A134: dss_ohautoclubohio220913_tblstudentenrollment | B134: s3://ace-da-mc-dss-datalake-us-west-2-847515726144/datalake/OHAutoClubOhio220913_tblStudentEnrollment/ | C134: ace_da_dss_datalake | D134: ace-da-dss-staging-to-datalake | E134: ace-da-dss-staging-to-datalake
A135: dss_ohautoclubohio220913_tblstudentinfo | B135: s3://ace-da-mc-dss-datalake-us-west-2-847515726144/datalake/OHAutoClubOhio220913_tblStudentInfo/ | C135: ace_da_dss_datalake | D135: ace-da-dss-staging-to-datalake | E135: ace-da-dss-staging-to-datalake
A136: dss_ohautoclubohio220913_tblvehicleinfo | B136: s3://ace-da-mc-dss-datalake-us-west-2-847515726144/datalake/OHAutoClubOhio220913_tblVehicleInfo/ | C136: ace_da_dss_datalake | D136: ace-da-dss-staging-to-datalake | E136: ace-da-dss-staging-to-datalake
...

Sheet Base
A1: BaseTable | B1: BaseS3Location | C1: BaseCrawler | D1: BaseGlueJob | E1: BaseControlM | F1: Helper Tables
A2: dss_mstadjustmenttypes | B2: s3://ace-da-mc-dss-base-us-west-2-847515726144/non_partitioned/mstadjustmenttypes/ | C2: None | D2: ace-da-dss-base-layer | E2: DEO1111O_DSS_AWS_MSTADJUSTMENTTYPES_TO_AWS_BASE_LOAD | F2: dss_caautoclubsocal201229_mstadjustmenttypes, dss_caautoclubtexas210622_mstadjustmenttypes, dss_meaaamaine211013_mstadjustmenttypes, dss_nhaaanh211015_mstadjustmenttypes, dss_ohautoclubohio220913_mstadjustmenttypes
A3: dss_mstappointmentstatus | B3: s3://ace-da-mc-dss-base-us-west-2-847515726144/non_partitioned/mstappointmentstatus/ | C3: None | D3: ace-da-dss-base-layer | E3: DEO1112O_DSS_AWS_MSTAPPOINTMENTSTATUS_TO_AWS_BASE_LOAD | F3: dss_caautoclubsocal201229_mstappointmentstatus, dss_caautoclubtexas210622_mstappointmentstatus, dss_meaaamaine211013_mstappointmentstatus, dss_nhaaanh211015_mstappointmentstatus, dss_ohautoclubohio220913_mstappointmentstatus
A4: dss_mstclassroomsessionstatus | B4: s3://ace-da-mc-dss-base-us-west-2-847515726144/non_partitioned/mstclassroomsessionstatus/ | C4: None | D4: ace-da-dss-base-layer | E4: DEO1113O_DSS_AWS_MSTCLASSROOMSESSIONSTATUS_TO_AWS_BASE_LOAD | F4: dss_caautoclubsocal201229_mstclassroomsessionstatus, dss_caautoclubtexas210622_mstclassroomsessionstatus, dss_meaaamaine211013_mstclassroomsessionstatus, dss_nhaaanh211015_mstclassroomsessionstatus, dss_ohautoclubohio220913_mstclassroomsessionstatus
A5: dss_mstclassroomstatus | B5: s3://ace-da-mc-dss-base-us-west-2-847515726144/non_partitioned/mstclassroomstatus/ | C5: None | D5: ace-da-dss-base-layer | E5: DEO1114O_DSS_AWS_MSTCLASSROOMSTATUS_TO_AWS_BASE_LOAD | F5: dss_caautoclubsocal201229_mstclassroomstatus, dss_caautoclubtexas210622_mstclassroomstatus, dss_meaaamaine211013_mstclassroomstatus, dss_nhaaanh211015_mstclassroomstatus, dss_ohautoclubohio220913_mstclassroomstatus
A6: dss_mstcreditcardtypes | B6: s3://ace-da-mc-dss-base-us-west-2-847515726144/non_partitioned/mstcreditcardtypes/ | C6: None | D6: ace-da-dss-base-layer | E6: DEO1115O_DSS_AWS_MSTCREDITCARDTYPES_TO_AWS_BASE_LOAD | F6: dss_caautoclubsocal201229_mstcreditcardtypes, dss_caautoclubtexas210622_mstcreditcardtypes, dss_meaaamaine211013_mstcreditcardtypes, dss_nhaaanh211015_mstcreditcardtypes, dss_ohautoclubohio220913_mstcreditcardtypes
A7: dss_mstpaymenttypes | B7: s3://ace-da-mc-dss-base-us-west-2-847515726144/non_partitioned/mstpaymenttypes/ | C7: None | D7: ace-da-dss-base-layer | E7: DEO1116O_DSS_AWS_MSTPAYMENTTYPES_TO_AWS_BASE_LOAD | F7: dss_caautoclubsocal201229_mstpaymenttypes, dss_caautoclubtexas210622_mstpaymenttypes, dss_meaaamaine211013_mstpaymenttypes, dss_nhaaanh211015_mstpaymenttypes, dss_ohautoclubohio220913_mstpaymenttypes
A8: dss_mststaffstatus | B8: s3://ace-da-mc-dss-base-us-west-2-847515726144/non_partitioned/mststaffstatus/ | C8: None | D8: ace-da-dss-base-layer | E8: DEO1117O_DSS_AWS_MSTSTAFFSTATUS_TO_AWS_BASE_LOAD | F8: dss_caautoclubsocal201229_mststaffstatus, dss_caautoclubtexas210622_mststaffstatus, dss_meaaamaine211013_mststaffstatus, dss_nhaaanh211015_mststaffstatus, dss_ohautoclubohio220913_mststaffstatus
A9: dss_mststafftype | B9: s3://ace-da-mc-dss-base-us-west-2-847515726144/non_partitioned/mststafftype/ | C9: None | D9: ace-da-dss-base-layer | E9: DEO1118O_DSS_AWS_MSTSTAFFTYPE_TO_AWS_BASE_LOAD | F9: dss_caautoclubsocal201229_mststafftype, dss_caautoclubtexas210622_mststafftype, dss_meaaamaine211013_mststafftype, dss_nhaaanh211015_mststafftype, dss_ohautoclubohio220913_mststafftype
A10: dss_mststudentstatus | B10: s3://ace-da-mc-dss-base-us-west-2-847515726144/non_partitioned/mststudentstatus/ | C10: None | D10: ace-da-dss-base-layer | E10: DEO1119O_DSS_AWS_MSTSTUDENTSTATUS_TO_AWS_BASE_LOAD | F10: dss_caautoclubsocal201229_mststudentstatus, dss_caautoclubtexas210622_mststudentstatus, dss_meaaamaine211013_mststudentstatus, dss_nhaaanh211015_mststudentstatus, dss_ohautoclubohio220913_mststudentstatus
A11: dss_mstvehiclestatus | B11: s3://ace-da-mc-dss-base-us-west-2-847515726144/non_partitioned/mstvehiclestatus/ | C11: None | D11: ace-da-dss-base-layer | E11: DEO1120O_DSS_AWS_MSTVEHICLESTATUS_TO_AWS_BASE_LOAD | F11: dss_caautoclubsocal201229_mstvehiclestatus, dss_caautoclubtexas210622_mstvehiclestatus, dss_meaaamaine211013_mstvehiclestatus, dss_nhaaanh211015_mstvehiclestatus, dss_ohautoclubohio220913_mstvehiclestatus
A12: dss_mstvehicletype | B12: s3://ace-da-mc-dss-base-us-west-2-847515726144/non_partitioned/mstvehicletype/ | C12: None | D12: ace-da-dss-base-layer | E12: DEO1121O_DSS_AWS_MSTVEHICLETYPE_TO_AWS_BASE_LOAD | F12: dss_caautoclubsocal201229_mstvehicletype, dss_caautoclubtexas210622_mstvehicletype, dss_meaaamaine211013_mstvehicletype, dss_nhaaanh211015_mstvehicletype, dss_ohautoclubohio220913_mstvehicletype
... A28: dss_tblvehicleinfo | B28: s3://ace-da-mc-dss-base-us-west-2-847515726144/partitoned/tblvehicleinfo/ | C28: ace_da_dss_base_partitoned | D28: ace-da-dss-base-layer | E28: DEO1110O_DSS_AWS_TBLVEHICLEINFO_TO_AWS_BASE_LOAD | F28: dss_caautoclubsocal201229_tblvehicleinfo, dss_caautoclubtexas210622_tblvehicleinfo, dss_meaaamaine211013_tblvehicleinfo, dss_nhaaanh211015_tblvehicleinfo, dss_ohautoclubohio220913_tblvehicleinfo

Sheet Master
A1: MasterTable | B1: MasterS3Location | C1: MasterCrawler | D1: MasterGlueJob | E1: MasterControlM | F1: Helper Tables | G1: SFTP Job | H1: SFTP Location
A2: dss_student_master | B2: s3://ace-da-mc-dss-master-us-west-2-847515726144/marketing_extract/ | C2: ace_da_dss_marketing_extract | D2: ace-da-dss-marketing-extract | E2: DEO1071O_DSS_AWS_DATALAKE_TO_AWS_MASTER_MARKETING_LOAD | F2: dss_tblstudentinfo, dss_tbllocation, dss_tblpackageinfo, dss_tblstudentenrollment, dss_tblstaffinfo | G2: DEO1152O_DSS_AWS_STUDENT_MASTER_TO_HDP | H2: /workspace/projects/dss/sh_scripts/dss_student_master.sh
A3: marketing_extract | B3: s3://ace-da-mc-dss-master-us-west-2-847515726144/dss_student_master/ | C3: None ( Iceberg table) | D3: ace-da-dss-student-master | E3: DEO1151O_DSS_STUDENT_MASTER_TO_AWS_MASTER_LOAD | F3: dss_tblstudentinfo | G3: MCE1428O_DSS_MktgFile_AWS_TO_Hadoop | H3: /workspace/projects/dss/sh_scripts/marketing_sftp.sh
